import logging
from unittest.mock import AsyncMock

import pytest

from app.core.exceptions import (
    OptScaleAPIResponseError,
    UserAccessTokenError,
    UserOrgCreationError,
)
from app.optscale_api.auth_api import OptScaleAuth
from app.optscale_api.orgs_api import OptScaleOrgAPI


@pytest.fixture
def optscale_org_api_instance():
    return OptScaleOrgAPI()


@pytest.fixture
def optscale_auth_api():
    return OptScaleAuth()


@pytest.fixture
def mock_api_client_post(mocker, optscale_org_api_instance):
    mock_post = mocker.patch.object(
        optscale_org_api_instance.api_client, "post", new=AsyncMock()
    )
    return mock_post


@pytest.fixture
def mock_api_client_get(mocker, optscale_org_api_instance):
    mock_get = mocker.patch.object(
        optscale_org_api_instance.api_client, "get", new=AsyncMock()
    )
    return mock_get


@pytest.fixture
def mock_auth_token(mocker, optscale_auth_api):
    mock_auth_token = mocker.patch.object(
        optscale_auth_api,
        "obtain_user_auth_token_with_admin_api_key",
        return_value="good token",
    )
    return mock_auth_token


@pytest.fixture
def mock_invalid_auth_token(mocker, optscale_auth_api):
    mock_auth_token = mocker.patch.object(
        optscale_auth_api,
        "obtain_user_auth_token_with_admin_api_key",
        side_effect=UserAccessTokenError("Failed to get an admin access token"),
    )
    return mock_auth_token


async def test_create_user_org(
    optscale_org_api_instance,
    mock_api_client_post,
    mock_auth_token,
    optscale_auth_api,
    test_data: dict,
):
    mock_api_client_post.return_value = test_data["org"]["case_create"]["response"]

    response = await optscale_org_api_instance.create_user_org(
        org_name="MyOrg",
        currency="USD",
        user_id="test_user",
        admin_api_key="test_key",
        auth_client=optscale_auth_api,
    )

    got = response
    want = test_data["org"]["case_create"]["response"]
    for k, v in want.items():
        assert (
            got[k] == v
        ), f"Mismatch in response for key '{k}': expected {v}, got {got[k]}"

    # Assert that mock_post was called with expected arguments
    mock_api_client_post.assert_called_once_with(
        endpoint="/restapi/v2/organizations",
        data={"name": "MyOrg", "currency": "USD"},
        headers={"Authorization": "Bearer good token"},
    )


async def test_create_user_org_with_invalid_currency(
    caplog,
    optscale_org_api_instance,
    mock_api_client_post,
    mock_auth_token,
    optscale_auth_api,
):
    with caplog.at_level(logging.ERROR):
        result = await optscale_org_api_instance.create_user_org(
            org_name="Test Org",
            currency="not valid currency",
            user_id="test_user",
            admin_api_key="test_key",
            auth_client=optscale_auth_api,
        )

        assert result is None, "Expected None for invalid currency"
        assert (
            "Invalid currency: not valid currency" in caplog.text
        ), "Expected error message for invalid currency"


async def test_get_user_org_with_no_token(
    optscale_org_api_instance,
    mock_api_client_post,
    mock_invalid_auth_token,
    optscale_auth_api,
    caplog,
):
    with caplog.at_level(logging.ERROR):
        with pytest.raises(
            UserAccessTokenError,
            match="Failed to get an admin access token",
        ):
            await optscale_org_api_instance.create_user_org(
                org_name="MyOrg",
                currency="USD",
                user_id="test_user",
                admin_api_key="test_key",
                auth_client=optscale_auth_api,
            )
    # Verify the log entry
    assert (
        "Failed to get an admin access token" in caplog.text
    ), "Expected error log message for the exception"  # noqa: E501


async def test_get_user_org_empty_response(
    optscale_org_api_instance, mock_api_client_get, mock_auth_token, optscale_auth_api
):
    mock_api_client_get.return_value = {"organizations": []}
    result = await optscale_org_api_instance.access_user_org_list_with_admin_key(
        user_id="test_user", admin_api_key="test_key", auth_client=optscale_auth_api
    )
    assert result == {"organizations": []}
    mock_api_client_get.assert_called_once_with(
        endpoint="/restapi/v2/organizations",
        headers={"Authorization": "Bearer good token"},
    )


async def test_get_user_org_response_error(
    optscale_org_api_instance,
    mock_api_client_get,
    mock_auth_token,
    optscale_auth_api,
    caplog,
):
    mock_api_client_get.return_value = {
        "error": "This is an error! ",
        "status_code": 403,
        "data": {"error": {"reason": "Oh no, I made a mistake!"}},
    }
    with caplog.at_level(logging.ERROR):
        with pytest.raises(
            OptScaleAPIResponseError, match="Error response from OptScale"
        ):  # noqa: PT012
            await optscale_org_api_instance.access_user_org_list_with_admin_key(
                user_id="test_user",
                admin_api_key="test_key",
                auth_client=optscale_auth_api,
            )


async def test_get_user_orgs_exceptions_handling(
    optscale_org_api_instance,
    mock_api_client_get,
    mock_auth_token,
    optscale_auth_api,
    caplog,
):
    mock_api_client_get.side_effect = UserAccessTokenError("Access Token exception")
    with caplog.at_level(logging.ERROR):
        with pytest.raises(UserAccessTokenError, match="Access Token exception"):
            await optscale_org_api_instance.access_user_org_list_with_admin_key(
                user_id="test_user",
                admin_api_key="test_key",
                auth_client=optscale_auth_api,
            )
    # Verify the log entry
    assert (
        "Failed to get access token for user test_user: Access Token exception"
        in caplog.text
    ), "Expected error log message for the exception"  # noqa: E501

    mock_api_client_get.side_effect = Exception("Generic Exception")
    with caplog.at_level(logging.ERROR):
        with pytest.raises(Exception, match="Generic Exception"):
            await optscale_org_api_instance.access_user_org_list_with_admin_key(
                user_id="test_user",
                admin_api_key="test_key",
                auth_client=optscale_auth_api,
            )
    # Verify the log entry
    assert (
        "Failed to get access token for user test_user: Access Token exception"
        in caplog.text
    ), "Expected error log message for the exception"  # noqa: E501


async def test_create_org_access_token_exception_handling(
    optscale_org_api_instance,
    mock_api_client_post,
    mock_auth_token,
    optscale_auth_api,
    caplog,
):
    # Simulate a UserAccessTokenError exception  in `create_user_org`
    mock_api_client_post.side_effect = UserAccessTokenError("Access Token exception")
    with caplog.at_level(logging.ERROR):
        with pytest.raises(UserAccessTokenError, match="Access Token exception"):
            await optscale_org_api_instance.create_user_org(
                org_name="MyOrg",
                currency="USD",
                user_id="test_user",
                admin_api_key="test_key",
                auth_client=optscale_auth_api,
            )
    # Verify the log entry
    assert (
        "Failed to get access token for user test_user: Access Token exception"
        in caplog.text
    ), "Expected error log message for the exception"  # noqa: E501


async def test_create_org_user_org_creation_exception_handling(
    optscale_org_api_instance,
    mock_api_client_post,
    mock_auth_token,
    optscale_auth_api,
    caplog,
):
    # Simulate a UserOrgCreationError exception  in `create_user_org`
    mock_api_client_post.side_effect = UserOrgCreationError("Org Creation exception")
    with caplog.at_level(logging.ERROR):
        with pytest.raises(UserOrgCreationError, match="Org Creation exception"):
            await optscale_org_api_instance.create_user_org(
                org_name="MyOrg",
                currency="USD",
                user_id="test_user",
                admin_api_key="test_key",
                auth_client=optscale_auth_api,
            )
    # Verify the log entry
    assert (
        "Exception occurred creating an organization on OptScale: Org Creation exception"
        in caplog.text
    ), "Expected error log message for the exception"  # noqa: E501


@pytest.mark.asyncio
@pytest.mark.parametrize(
    "side_effect, expected_exception, expected_message",  # noqa: PT006
    [
        (
            Exception("Test Exception"),
            Exception,
            "Exception occurred creating an organization on OptScale: Test Exception",
        ),
        (
            UserAccessTokenError("User Access Token not valid"),
            UserAccessTokenError,
            "Failed to get access token for user test_user: User Access Token not valid",
        ),
    ],
)
async def test_create_org_user_exception_handling(
    optscale_org_api_instance,
    mock_api_client_post,
    mock_auth_token,
    optscale_auth_api,
    caplog,
    side_effect,
    expected_exception,
    expected_message,
):
    mock_api_client_post.side_effect = side_effect
    with caplog.at_level(logging.ERROR):
        with pytest.raises(expected_exception, match=str(side_effect)):
            await optscale_org_api_instance.create_user_org(
                org_name="MyOrg",
                currency="USD",
                user_id="test_user",
                admin_api_key="test_key",
                auth_client=optscale_auth_api,
            )
    assert any(expected_message in record.message for record in caplog.records)


async def test_create_org_user_response_error(
    optscale_org_api_instance,
    mock_api_client_post,
    mock_auth_token,
    optscale_auth_api,
    caplog,
):
    mock_api_client_post.return_value = {
        "status_code": 403,
        "error": "Invalid JSON format in response",
    }
    with caplog.at_level(logging.ERROR):
        with pytest.raises(OptScaleAPIResponseError) as exc_info:
            await optscale_org_api_instance.create_user_org(
                org_name="MyOrg",
                currency="USD",
                user_id="test_user",
                admin_api_key="test_key",
                auth_client=optscale_auth_api,
            )

        exception = exc_info.value
        assert exception.title == "Error response from OptScale"
        assert exception.reason == "No details available"
        assert exception.status_code == 403

        # check the logging message printed by the create_user_org
        assert any(
            "An error occurred creating an organization for user test_user."
            in record.message
            for record in caplog.records
        )
        # check the logging message printed by the OptScaleAPIResponseError
        assert any(
            "Exception occurred creating an organization on OptScale: Error response from OptScale"
            in record.message
            for record in caplog.records
        )
